Loaded dependency [python3/3.11.7]: gcc/12.3.0-binutils-2.40
Loaded dependency [python3/3.11.7]: sqlite3/3.44.2
Loaded module: python3/3.11.7

Loading python3/3.11.7
  Loading requirement: gcc/12.3.0-binutils-2.40 sqlite3/3.44.2
Loaded module: cuda/11.8
wandb: Currently logged in as: yuch0001 (uncertaintyquantification-dtu). Use `wandb login --relogin` to force relogin
Traceback (most recent call last):
  File "/work3/s194241/MastersThesis/MT/lib/python3.11/site-packages/wandb/sdk/wandb_init.py", line 1176, in init
    run = wi.init()
          ^^^^^^^^^
  File "/work3/s194241/MastersThesis/MT/lib/python3.11/site-packages/wandb/sdk/wandb_init.py", line 633, in init
    run = Run(
          ^^^^
  File "/work3/s194241/MastersThesis/MT/lib/python3.11/site-packages/wandb/sdk/wandb_run.py", line 566, in __init__
    self._init(
  File "/work3/s194241/MastersThesis/MT/lib/python3.11/site-packages/wandb/sdk/wandb_run.py", line 676, in _init
    self._config._update(config, ignore_locked=True)
  File "/work3/s194241/MastersThesis/MT/lib/python3.11/site-packages/wandb/sdk/wandb_config.py", line 177, in _update
    sanitized = self._sanitize_dict(
                ^^^^^^^^^^^^^^^^^^^^
  File "/work3/s194241/MastersThesis/MT/lib/python3.11/site-packages/wandb/sdk/wandb_config.py", line 264, in _sanitize_dict
    k, v = self._sanitize(k, v, allow_val_change)
           ^^^^^^^^^^^^^^^^^^^^^^^^^^^^^^^^^^^^^^
  File "/work3/s194241/MastersThesis/MT/lib/python3.11/site-packages/wandb/sdk/wandb_config.py", line 282, in _sanitize
    val = json_friendly_val(val)
          ^^^^^^^^^^^^^^^^^^^^^^
  File "/work3/s194241/MastersThesis/MT/lib/python3.11/site-packages/wandb/util.py", line 671, in json_friendly_val
    converted = asdict(val)
                ^^^^^^^^^^^
  File "/appl/python/3.11.7/lib/python3.11/dataclasses.py", line 1284, in asdict
    return _asdict_inner(obj, dict_factory)
           ^^^^^^^^^^^^^^^^^^^^^^^^^^^^^^^^
  File "/appl/python/3.11.7/lib/python3.11/dataclasses.py", line 1291, in _asdict_inner
    value = _asdict_inner(getattr(obj, f.name), dict_factory)
            ^^^^^^^^^^^^^^^^^^^^^^^^^^^^^^^^^^^^^^^^^^^^^^^^^
  File "/appl/python/3.11.7/lib/python3.11/dataclasses.py", line 1321, in _asdict_inner
    return type(obj)((_asdict_inner(k, dict_factory),
           ^^^^^^^^^^^^^^^^^^^^^^^^^^^^^^^^^^^^^^^^^^
TypeError: first argument must be callable or None
Error executing job with overrides: ['experiments=train_classification_MIMO']
Traceback (most recent call last):
  File "/work3/s194241/MastersThesis/MT/lib/python3.11/site-packages/wandb/sdk/wandb_init.py", line 1176, in init
    run = wi.init()
          ^^^^^^^^^
  File "/work3/s194241/MastersThesis/MT/lib/python3.11/site-packages/wandb/sdk/wandb_init.py", line 633, in init
    run = Run(
          ^^^^
  File "/work3/s194241/MastersThesis/MT/lib/python3.11/site-packages/wandb/sdk/wandb_run.py", line 566, in __init__
    self._init(
  File "/work3/s194241/MastersThesis/MT/lib/python3.11/site-packages/wandb/sdk/wandb_run.py", line 676, in _init
    self._config._update(config, ignore_locked=True)
  File "/work3/s194241/MastersThesis/MT/lib/python3.11/site-packages/wandb/sdk/wandb_config.py", line 177, in _update
    sanitized = self._sanitize_dict(
                ^^^^^^^^^^^^^^^^^^^^
  File "/work3/s194241/MastersThesis/MT/lib/python3.11/site-packages/wandb/sdk/wandb_config.py", line 264, in _sanitize_dict
    k, v = self._sanitize(k, v, allow_val_change)
           ^^^^^^^^^^^^^^^^^^^^^^^^^^^^^^^^^^^^^^
  File "/work3/s194241/MastersThesis/MT/lib/python3.11/site-packages/wandb/sdk/wandb_config.py", line 282, in _sanitize
    val = json_friendly_val(val)
          ^^^^^^^^^^^^^^^^^^^^^^
  File "/work3/s194241/MastersThesis/MT/lib/python3.11/site-packages/wandb/util.py", line 671, in json_friendly_val
    converted = asdict(val)
                ^^^^^^^^^^^
  File "/appl/python/3.11.7/lib/python3.11/dataclasses.py", line 1284, in asdict
    return _asdict_inner(obj, dict_factory)
           ^^^^^^^^^^^^^^^^^^^^^^^^^^^^^^^^
  File "/appl/python/3.11.7/lib/python3.11/dataclasses.py", line 1291, in _asdict_inner
    value = _asdict_inner(getattr(obj, f.name), dict_factory)
            ^^^^^^^^^^^^^^^^^^^^^^^^^^^^^^^^^^^^^^^^^^^^^^^^^
  File "/appl/python/3.11.7/lib/python3.11/dataclasses.py", line 1321, in _asdict_inner
    return type(obj)((_asdict_inner(k, dict_factory),
           ^^^^^^^^^^^^^^^^^^^^^^^^^^^^^^^^^^^^^^^^^^
TypeError: first argument must be callable or None

The above exception was the direct cause of the following exception:

Traceback (most recent call last):
  File "/work3/s194241/MastersThesis/src/train_classification.py", line 200, in main
    wandb.init(
  File "/work3/s194241/MastersThesis/MT/lib/python3.11/site-packages/wandb/sdk/wandb_init.py", line 1214, in init
    raise Error("An unexpected error occurred") from error_seen
wandb.errors.Error: An unexpected error occurred

Set the environment variable HYDRA_FULL_ERROR=1 for a complete stack trace.
